<?xml version="1.0" ?>
<!-- =================================================================================== -->
<!-- |    This document was autogenerated by xacro from r2d2.xacro                     | -->
<!-- |    EDITING THIS FILE BY HAND IS NOT RECOMMENDED                                 | -->
<!-- =================================================================================== -->
<robot name="r2d2" xmlns:xacro="http://ros.org/wiki/xacro">
  <material name="blue">
    <color rgba="0 0 .8 1"/>
  </material>
  <material name="black">
    <color rgba="0 0 0 1"/>
  </material>
  <material name="white">
    <color rgba="1 1 1 1"/>
  </material>
  <link name="base_link">
    <visual>
      <geometry>
        <cylinder length="0.6" radius="0.2"/>
      </geometry>
      <material name="blue"/>
    </visual>
    <collision>
      <geometry>
        <cylinder length="0.6" radius="0.2"/>
      </geometry>
    </collision>
    <inertial>
      <mass value="10"/>
      <inertia ixx="1.0" ixy="0.0" ixz="0.0" iyy="1.0" iyz="0.0" izz="1.0"/>
    </inertial>
  </link>
  <link name="right_leg">
    <visual>
      <geometry>
        <box size="0.6 .1 .2"/>
      </geometry>
      <origin rpy="0 1.57075 0" xyz="0 0 -0.3"/>
      <material name="white"/>
      <gazebo>
        <material>Gazebo/White</material>
      </gazebo>
    </visual>
    <collision>
      <geometry>
        <box size="0.6 .1 .2"/>
      </geometry>
      <origin rpy="0 1.57075 0" xyz="0 0 -0.3"/>
    </collision>
    <inertial>
      <mass value="10"/>
      <inertia ixx="1.0" ixy="0.0" ixz="0.0" iyy="1.0" iyz="0.0" izz="1.0"/>
    </inertial>
  </link>
  <joint name="base_to_right_leg" type="fixed">
    <parent link="base_link"/>
    <child link="right_leg"/>
    <origin xyz="0 -0.22 .25"/>
  </joint>
  <link name="right_base">
    <visual>
      <geometry>
        <box size="0.4 .1 .1"/>
      </geometry>
      <material name="white"/>
    </visual>
    <collision>
      <geometry>
        <box size="0.4 .1 .1"/>
      </geometry>
    </collision>
    <inertial>
      <mass value="10"/>
      <inertia ixx="1.0" ixy="0.0" ixz="0.0" iyy="1.0" iyz="0.0" izz="1.0"/>
    </inertial>
  </link>
  <joint name="right_base_joint" type="fixed">
    <parent link="right_leg"/>
    <child link="right_base"/>
    <origin xyz="0 0 -0.6"/>
  </joint>
  <link name="right_front_wheel">
    <visual>
      <origin rpy="1.57075 0 0" xyz="0 0 0"/>
      <geometry>
        <cylinder length="0.1" radius="0.035"/>
      </geometry>
      <material name="black"/>
      <origin rpy="0 0 0" xyz="0 0 0"/>
    </visual>
    <collision>
      <origin rpy="1.57075 0 0" xyz="0 0 0"/>
      <geometry>
        <cylinder length="0.1" radius="0.035"/>
      </geometry>
      <origin rpy="0 0 0" xyz="0 0 0"/>
    </collision>
    <inertial>
      <mass value="1"/>
      <inertia ixx="1.0" ixy="0.0" ixz="0.0" iyy="1.0" iyz="0.0" izz="1.0"/>
    </inertial>
  </link>
  <joint name="right_front_wheel_joint" type="continuous">
    <axis rpy="0 0 0" xyz="0 1 0"/>
    <parent link="right_base"/>
    <child link="right_front_wheel"/>
    <origin rpy="0 0 0" xyz="0.133333333333 0 -0.085"/>
  </joint>
  <!-- This block provides the simulator (Gazebo) with information on a few additional
    physical properties. See http://gazebosim.org/tutorials/?tut=ros_urdf for more-->
  <gazebo reference="right_front_wheel">
    <mu1 value="200.0"/>
    <mu2 value="100.0"/>
    <kp value="10000000.0"/>
    <kd value="1.0"/>
    <material>Gazebo/Grey</material>
  </gazebo>
  <!-- This block connects the wheel joint to an actuator (motor), which informs both
    simulation and visualization of the robot -->
  <transmission name="right_front_wheel_trans" type="SimpleTransmission">
    <type>transmission_interface/SimpleTransmission</type>
    <actuator name="right_front_wheel_motor">
      <mechanicalReduction>1</mechanicalReduction>
    </actuator>
    <joint name="right_front_wheel_joint">
      <hardwareInterface>VelocityJointInterface</hardwareInterface>
    </joint>
  </transmission>
  <link name="right_back_wheel">
    <visual>
      <origin rpy="1.57075 0 0" xyz="0 0 0"/>
      <geometry>
        <cylinder length="0.1" radius="0.035"/>
      </geometry>
      <material name="black"/>
      <origin rpy="0 0 0" xyz="0 0 0"/>
    </visual>
    <collision>
      <origin rpy="1.57075 0 0" xyz="0 0 0"/>
      <geometry>
        <cylinder length="0.1" radius="0.035"/>
      </geometry>
      <origin rpy="0 0 0" xyz="0 0 0"/>
    </collision>
    <inertial>
      <mass value="1"/>
      <inertia ixx="1.0" ixy="0.0" ixz="0.0" iyy="1.0" iyz="0.0" izz="1.0"/>
    </inertial>
  </link>
  <joint name="right_back_wheel_joint" type="continuous">
    <axis rpy="0 0 0" xyz="0 1 0"/>
    <parent link="right_base"/>
    <child link="right_back_wheel"/>
    <origin rpy="0 0 0" xyz="-0.133333333333 0 -0.085"/>
  </joint>
  <!-- This block provides the simulator (Gazebo) with information on a few additional
    physical properties. See http://gazebosim.org/tutorials/?tut=ros_urdf for more-->
  <gazebo reference="right_back_wheel">
    <mu1 value="200.0"/>
    <mu2 value="100.0"/>
    <kp value="10000000.0"/>
    <kd value="1.0"/>
    <material>Gazebo/Grey</material>
  </gazebo>
  <!-- This block connects the wheel joint to an actuator (motor), which informs both
    simulation and visualization of the robot -->
  <transmission name="right_back_wheel_trans" type="SimpleTransmission">
    <type>transmission_interface/SimpleTransmission</type>
    <actuator name="right_back_wheel_motor">
      <mechanicalReduction>1</mechanicalReduction>
    </actuator>
    <joint name="right_back_wheel_joint">
      <hardwareInterface>VelocityJointInterface</hardwareInterface>
    </joint>
  </transmission>
  <link name="left_leg">
    <visual>
      <geometry>
        <box size="0.6 .1 .2"/>
      </geometry>
      <origin rpy="0 1.57075 0" xyz="0 0 -0.3"/>
      <material name="white"/>
    </visual>
    <collision>
      <geometry>
        <box size="0.6 .1 .2"/>
      </geometry>
      <origin rpy="0 1.57075 0" xyz="0 0 -0.3"/>
    </collision>
    <inertial>
      <mass value="10"/>
      <inertia ixx="1.0" ixy="0.0" ixz="0.0" iyy="1.0" iyz="0.0" izz="1.0"/>
    </inertial>
  </link>
  <joint name="base_to_left_leg" type="fixed">
    <parent link="base_link"/>
    <child link="left_leg"/>
    <origin xyz="0 0.22 .25"/>
  </joint>
  <link name="left_base">
    <visual>
      <geometry>
        <box size="0.4 .1 .1"/>
      </geometry>
      <material name="white"/>
    </visual>
    <collision>
      <geometry>
        <box size="0.4 .1 .1"/>
      </geometry>
    </collision>
    <inertial>
      <mass value="10"/>
      <inertia ixx="1.0" ixy="0.0" ixz="0.0" iyy="1.0" iyz="0.0" izz="1.0"/>
    </inertial>
  </link>
  <joint name="left_base_joint" type="fixed">
    <parent link="left_leg"/>
    <child link="left_base"/>
    <origin xyz="0 0 -0.6"/>
  </joint>
  <link name="left_front_wheel">
    <visual>
      <origin rpy="1.57075 0 0" xyz="0 0 0"/>
      <geometry>
        <cylinder length="0.1" radius="0.035"/>
      </geometry>
      <material name="black"/>
      <origin rpy="0 0 0" xyz="0 0 0"/>
    </visual>
    <collision>
      <origin rpy="1.57075 0 0" xyz="0 0 0"/>
      <geometry>
        <cylinder length="0.1" radius="0.035"/>
      </geometry>
      <origin rpy="0 0 0" xyz="0 0 0"/>
    </collision>
    <inertial>
      <mass value="1"/>
      <inertia ixx="1.0" ixy="0.0" ixz="0.0" iyy="1.0" iyz="0.0" izz="1.0"/>
    </inertial>
  </link>
  <joint name="left_front_wheel_joint" type="continuous">
    <axis rpy="0 0 0" xyz="0 1 0"/>
    <parent link="left_base"/>
    <child link="left_front_wheel"/>
    <origin rpy="0 0 0" xyz="0.133333333333 0 -0.085"/>
  </joint>
  <!-- This block provides the simulator (Gazebo) with information on a few additional
    physical properties. See http://gazebosim.org/tutorials/?tut=ros_urdf for more-->
  <gazebo reference="left_front_wheel">
    <mu1 value="200.0"/>
    <mu2 value="100.0"/>
    <kp value="10000000.0"/>
    <kd value="1.0"/>
    <material>Gazebo/Grey</material>
  </gazebo>
  <!-- This block connects the wheel joint to an actuator (motor), which informs both
    simulation and visualization of the robot -->
  <transmission name="left_front_wheel_trans" type="SimpleTransmission">
    <type>transmission_interface/SimpleTransmission</type>
    <actuator name="left_front_wheel_motor">
      <mechanicalReduction>1</mechanicalReduction>
    </actuator>
    <joint name="left_front_wheel_joint">
      <hardwareInterface>VelocityJointInterface</hardwareInterface>
    </joint>
  </transmission>
  <link name="left_back_wheel">
    <visual>
      <origin rpy="1.57075 0 0" xyz="0 0 0"/>
      <geometry>
        <cylinder length="0.1" radius="0.035"/>
      </geometry>
      <material name="black"/>
      <origin rpy="0 0 0" xyz="0 0 0"/>
    </visual>
    <collision>
      <origin rpy="1.57075 0 0" xyz="0 0 0"/>
      <geometry>
        <cylinder length="0.1" radius="0.035"/>
      </geometry>
      <origin rpy="0 0 0" xyz="0 0 0"/>
    </collision>
    <inertial>
      <mass value="1"/>
      <inertia ixx="1.0" ixy="0.0" ixz="0.0" iyy="1.0" iyz="0.0" izz="1.0"/>
    </inertial>
  </link>
  <joint name="left_back_wheel_joint" type="continuous">
    <axis rpy="0 0 0" xyz="0 1 0"/>
    <parent link="left_base"/>
    <child link="left_back_wheel"/>
    <origin rpy="0 0 0" xyz="-0.133333333333 0 -0.085"/>
  </joint>
  <!-- This block provides the simulator (Gazebo) with information on a few additional
    physical properties. See http://gazebosim.org/tutorials/?tut=ros_urdf for more-->
  <gazebo reference="left_back_wheel">
    <mu1 value="200.0"/>
    <mu2 value="100.0"/>
    <kp value="10000000.0"/>
    <kd value="1.0"/>
    <material>Gazebo/Grey</material>
  </gazebo>
  <!-- This block connects the wheel joint to an actuator (motor), which informs both
    simulation and visualization of the robot -->
  <transmission name="left_back_wheel_trans" type="SimpleTransmission">
    <type>transmission_interface/SimpleTransmission</type>
    <actuator name="left_back_wheel_motor">
      <mechanicalReduction>1</mechanicalReduction>
    </actuator>
    <joint name="left_back_wheel_joint">
      <hardwareInterface>VelocityJointInterface</hardwareInterface>
    </joint>
  </transmission>
  <joint name="gripper_extension" type="prismatic">
    <parent link="base_link"/>
    <child link="gripper_pole"/>
    <limit effort="1000.0" lower="-0.38" upper="0" velocity="0.5"/>
    <origin rpy="0 0 0" xyz="0.19 0 .2"/>
    <limit effort="30" velocity="0.2"/>
    <dynamics damping="0.0" friction="0.0"/>
  </joint>
  <link name="gripper_pole">
    <visual>
      <geometry>
        <cylinder length="0.2" radius=".01"/>
      </geometry>
      <origin rpy="0 1.57075 0 " xyz="0.1 0 0"/>
    </visual>
    <collision>
      <geometry>
        <cylinder length="0.2" radius=".01"/>
      </geometry>
      <origin rpy="0 1.57075 0 " xyz="0.1 0 0"/>
    </collision>
    <inertial>
      <mass value="0.05"/>
      <inertia ixx="1.0" ixy="0.0" ixz="0.0" iyy="1.0" iyz="0.0" izz="1.0"/>
    </inertial>
  </link>
  <transmission name="gripper_extension_trans" type="SimpleTransmission">
    <type>transmission_interface/SimpleTransmission</type>
    <actuator name="gripper_extension_motor">
      <mechanicalReduction>1</mechanicalReduction>
    </actuator>
    <joint name="gripper_extension">
      <hardwareInterface>PositionJointInterface</hardwareInterface>
    </joint>
  </transmission>
  <joint name="left_gripper_joint" type="revolute">
    <axis xyz="0 0 1"/>
    <limit effort="1000.0" lower="0.0" upper="0.548" velocity="0.5"/>
    <origin rpy="0 0 0" xyz="0.2 0.01 0"/>
    <parent link="gripper_pole"/>
    <child link="left_gripper"/>
    <limit effort="30" velocity="1.0"/>
    <dynamics damping="0.0" friction="0.0"/>
  </joint>
  <link name="left_gripper">
    <visual>
      <origin rpy="0.0 0 0" xyz="0 0 0"/>
      <geometry>
        <mesh filename="package://pr2_description/meshes/gripper_v0/l_finger.dae"/>
      </geometry>
    </visual>
    <collision>
      <geometry>
        <mesh filename="package://pr2_description/meshes/gripper_v0/l_finger.dae"/>
      </geometry>
      <origin rpy="0.0 0 0" xyz="0 0 0"/>
    </collision>
    <inertial>
      <mass value="0.05"/>
      <inertia ixx="1.0" ixy="0.0" ixz="0.0" iyy="1.0" iyz="0.0" izz="1.0"/>
    </inertial>
  </link>
  <transmission name="left_gripper_trans" type="SimpleTransmission">
    <type>transmission_interface/SimpleTransmission</type>
    <actuator name="left_gripper_motor">
      <mechanicalReduction>1</mechanicalReduction>
    </actuator>
    <joint name="left_gripper_joint">
      <hardwareInterface>PositionJointInterface</hardwareInterface>
    </joint>
  </transmission>
  <joint name="left_tip_joint" type="fixed">
    <parent link="left_gripper"/>
    <child link="left_tip"/>
  </joint>
  <link name="left_tip">
    <visual>
      <origin rpy="0.0 0 0" xyz="0.09137 0.00495 0"/>
      <geometry>
        <mesh filename="package://pr2_description/meshes/gripper_v0/l_finger_tip.dae"/>
      </geometry>
    </visual>
    <collision>
      <geometry>
        <mesh filename="package://pr2_description/meshes/gripper_v0/l_finger_tip.dae"/>
      </geometry>
      <origin rpy="0.0 0 0" xyz="0.09137 0.00495 0"/>
    </collision>
    <inertial>
      <mass value="0.05"/>
      <inertia ixx="1.0" ixy="0.0" ixz="0.0" iyy="1.0" iyz="0.0" izz="1.0"/>
    </inertial>
  </link>
  <joint name="right_gripper_joint" type="revolute">
    <axis xyz="0 0 -1"/>
    <limit effort="1000.0" lower="0.0" upper="0.548" velocity="0.5"/>
    <origin rpy="0 0 0" xyz="0.2 -0.01 0"/>
    <parent link="gripper_pole"/>
    <child link="right_gripper"/>
    <limit effort="30" velocity="1.0"/>
    <dynamics damping="0.0" friction="0.0"/>
  </joint>
  <link name="right_gripper">
    <visual>
      <origin rpy="-3.1415 0 0" xyz="0 0 0"/>
      <geometry>
        <mesh filename="package://pr2_description/meshes/gripper_v0/l_finger.dae"/>
      </geometry>
    </visual>
    <collision>
      <geometry>
        <mesh filename="package://pr2_description/meshes/gripper_v0/l_finger.dae"/>
      </geometry>
      <origin rpy="-3.1415 0 0" xyz="0 0 0"/>
    </collision>
    <inertial>
      <mass value="0.05"/>
      <inertia ixx="1.0" ixy="0.0" ixz="0.0" iyy="1.0" iyz="0.0" izz="1.0"/>
    </inertial>
  </link>
  <transmission name="right_gripper_trans" type="SimpleTransmission">
    <type>transmission_interface/SimpleTransmission</type>
    <actuator name="right_gripper_motor">
      <mechanicalReduction>1</mechanicalReduction>
    </actuator>
    <joint name="right_gripper_joint">
      <hardwareInterface>PositionJointInterface</hardwareInterface>
    </joint>
  </transmission>
  <joint name="right_tip_joint" type="fixed">
    <parent link="right_gripper"/>
    <child link="right_tip"/>
  </joint>
  <link name="right_tip">
    <visual>
      <origin rpy="-3.1415 0 0" xyz="0.09137 0.00495 0"/>
      <geometry>
        <mesh filename="package://pr2_description/meshes/gripper_v0/l_finger_tip.dae"/>
      </geometry>
    </visual>
    <collision>
      <geometry>
        <mesh filename="package://pr2_description/meshes/gripper_v0/l_finger_tip.dae"/>
      </geometry>
      <origin rpy="-3.1415 0 0" xyz="0.09137 0.00495 0"/>
    </collision>
    <inertial>
      <mass value="0.05"/>
      <inertia ixx="1.0" ixy="0.0" ixz="0.0" iyy="1.0" iyz="0.0" izz="1.0"/>
    </inertial>
  </link>
  <link name="head">
    <visual>
      <geometry>
        <sphere radius="0.2"/>
      </geometry>
      <material name="white"/>
    </visual>
    <collision>
      <geometry>
        <sphere radius="0.2"/>
      </geometry>
    </collision>
    <inertial>
      <mass value="2"/>
      <inertia ixx="1.0" ixy="0.0" ixz="0.0" iyy="1.0" iyz="0.0" izz="1.0"/>
    </inertial>
  </link>
  <joint name="head_swivel" type="continuous">
    <parent link="base_link"/>
    <child link="head"/>
    <axis xyz="0 0 1"/>
    <origin xyz="0 0 0.3"/>
    <limit effort="30" velocity="1.0"/>
    <dynamics damping="0.0" friction="0.0"/>
  </joint>
  <!-- This block connects the head_swivel joint to an actuator (motor), which informs both
  simulation and visualization of the robot -->
  <transmission name="head_swivel_trans" type="SimpleTransmission">
    <type>transmission_interface/SimpleTransmission</type>
    <actuator name="$head_swivel_motor">
      <mechanicalReduction>1</mechanicalReduction>
    </actuator>
    <joint name="head_swivel">
      <hardwareInterface>PositionJointInterface</hardwareInterface>
    </joint>
  </transmission>
  <link name="box">
    <visual>
      <geometry>
        <box size=".08 .08 .08"/>
      </geometry>
      <material name="blue"/>
      <origin xyz="-0.04 0 0"/>
    </visual>
    <collision>
      <geometry>
        <box size=".08 .08 .08"/>
      </geometry>
    </collision>
    <inertial>
      <mass value="1"/>
      <inertia ixx="1.0" ixy="0.0" ixz="0.0" iyy="1.0" iyz="0.0" izz="1.0"/>
    </inertial>
  </link>
  <joint name="tobox" type="fixed">
    <parent link="head"/>
    <child link="box"/>
    <origin xyz="0.1814 0 0.1414"/>
  </joint>
   <gazebo reference="box">
    <sensor type="multicamera" name="stereo_camera">
      <update_rate>30.0</update_rate>
      <camera name="left">
        <horizontal_fov>1.3962634</horizontal_fov>
        <image>
          <width>800</width>
          <height>800</height>
          <format>R8G8B8</format>
        </image>
        <clip>
          <near>0.02</near>
          <far>300</far>
        </clip>
        <noise>
          <type>gaussian</type>
          <mean>0.0</mean>
          <stddev>0.007</stddev>
        </noise>
      </camera>
      <camera name="right">
        <pose>0 -0.07 0 0 0 0</pose>
        <horizontal_fov>1.3962634</horizontal_fov>
        <image>
          <width>800</width>
          <height>800</height>
          <format>R8G8B8</format>
        </image>
        <clip>
          <near>0.02</near>
          <far>300</far>
        </clip>
        <noise>
          <type>gaussian</type>
          <mean>0.0</mean>
          <stddev>0.007</stddev>
        </noise>
      </camera>
      <plugin name="stereo_camera_controller" filename="libgazebo_ros_multicamera.so">
        <alwaysOn>true</alwaysOn>
        <updateRate>0.0</updateRate>
        <cameraName>multisense_sl/camera</cameraName>
        <imageTopicName>image_raw</imageTopicName>
        <cameraInfoTopicName>camera_info</cameraInfoTopicName>
        <frameName>left_camera_optical_frame</frameName>
        <rightFrameName>right_camera_optical_frame</rightFrameName>
        <hackBaseline>0.07</hackBaseline>
        <distortionK1>0.0</distortionK1>
        <distortionK2>0.0</distortionK2>
        <distortionK3>0.0</distortionK3>
        <distortionT1>0.0</distortionT1>
        <distortionT2>0.0</distortionT2>
      </plugin>
    </sensor>
  </gazebo>
  <!-- Gazebo plugin for ROS Control -->
  <gazebo>
    <plugin filename="libgazebo_ros_control.so" name="gazebo_ros_control">
      <robotNamespace>/</robotNamespace>
    </plugin>
  </gazebo>
</robot>

